Traceback (most recent call last):
  File "C:\Users\USER\AppData\Local\Programs\Python\Python312\Lib\site-packages\jupyter_cache\executors\utils.py", line 58, in single_nb_execution
    executenb(
  File "C:\Users\USER\AppData\Local\Programs\Python\Python312\Lib\site-packages\nbclient\client.py", line 1319, in execute
    return NotebookClient(nb=nb, resources=resources, km=km, **kwargs).execute()
           ^^^^^^^^^^^^^^^^^^^^^^^^^^^^^^^^^^^^^^^^^^^^^^^^^^^^^^^^^^^^^^^^^^^^^
  File "C:\Users\USER\AppData\Local\Programs\Python\Python312\Lib\site-packages\jupyter_core\utils\__init__.py", line 165, in wrapped
    return loop.run_until_complete(inner)
           ^^^^^^^^^^^^^^^^^^^^^^^^^^^^^^
  File "C:\Users\USER\AppData\Local\Programs\Python\Python312\Lib\asyncio\base_events.py", line 687, in run_until_complete
    return future.result()
           ^^^^^^^^^^^^^^^
  File "C:\Users\USER\AppData\Local\Programs\Python\Python312\Lib\site-packages\nbclient\client.py", line 709, in async_execute
    await self.async_execute_cell(
  File "C:\Users\USER\AppData\Local\Programs\Python\Python312\Lib\site-packages\nbclient\client.py", line 1062, in async_execute_cell
    await self._check_raise_for_error(cell, cell_index, exec_reply)
  File "C:\Users\USER\AppData\Local\Programs\Python\Python312\Lib\site-packages\nbclient\client.py", line 918, in _check_raise_for_error
    raise CellExecutionError.from_cell_and_msg(cell, exec_reply_content)
nbclient.exceptions.CellExecutionError: An error occurred while executing the following cell:
------------------
import csv

file_path = r"C:\Users\Vanu\OneDrive\Attachments\heart_attack_prediction_dataset.csv"  # Full file path

# Open and reading the CSV file
with open(file_path, 'r') as file:
    csv_reader = csv.reader(file)
    headers = next(csv_reader)  # Reading the header row
    data = list(csv_reader)     # Reading the rest of the rows

# first few rows to confirm successful loading
print("Headers:", headers)
print("First row:", data[0])


------------------


[1;31m---------------------------------------------------------------------------[0m
[1;31mFileNotFoundError[0m                         Traceback (most recent call last)
Cell [1;32mIn[1], line 6[0m
[0;32m      3[0m file_path [38;5;241m=[39m [38;5;124mr[39m[38;5;124m"[39m[38;5;124mC:[39m[38;5;124m\[39m[38;5;124mUsers[39m[38;5;124m\[39m[38;5;124mVanu[39m[38;5;124m\[39m[38;5;124mOneDrive[39m[38;5;124m\[39m[38;5;124mAttachments[39m[38;5;124m\[39m[38;5;124mheart_attack_prediction_dataset.csv[39m[38;5;124m"[39m  [38;5;66;03m# Full file path[39;00m
[0;32m      5[0m [38;5;66;03m# Open and reading the CSV file[39;00m
[1;32m----> 6[0m [38;5;28;01mwith[39;00m [38;5;28;43mopen[39;49m[43m([49m[43mfile_path[49m[43m,[49m[43m [49m[38;5;124;43m'[39;49m[38;5;124;43mr[39;49m[38;5;124;43m'[39;49m[43m)[49m [38;5;28;01mas[39;00m file:
[0;32m      7[0m     csv_reader [38;5;241m=[39m csv[38;5;241m.[39mreader(file)
[0;32m      8[0m     headers [38;5;241m=[39m [38;5;28mnext[39m(csv_reader)  [38;5;66;03m# Reading the header row[39;00m

File [1;32m~\AppData\Local\Programs\Python\Python312\Lib\site-packages\IPython\core\interactiveshell.py:324[0m, in [0;36m_modified_open[1;34m(file, *args, **kwargs)[0m
[0;32m    317[0m [38;5;28;01mif[39;00m file [38;5;129;01min[39;00m {[38;5;241m0[39m, [38;5;241m1[39m, [38;5;241m2[39m}:
[0;32m    318[0m     [38;5;28;01mraise[39;00m [38;5;167;01mValueError[39;00m(
[0;32m    319[0m         [38;5;124mf[39m[38;5;124m"[39m[38;5;124mIPython won[39m[38;5;124m'[39m[38;5;124mt let you open fd=[39m[38;5;132;01m{[39;00mfile[38;5;132;01m}[39;00m[38;5;124m by default [39m[38;5;124m"[39m
[0;32m    320[0m         [38;5;124m"[39m[38;5;124mas it is likely to crash IPython. If you know what you are doing, [39m[38;5;124m"[39m
[0;32m    321[0m         [38;5;124m"[39m[38;5;124myou can use builtins[39m[38;5;124m'[39m[38;5;124m open.[39m[38;5;124m"[39m
[0;32m    322[0m     )
[1;32m--> 324[0m [38;5;28;01mreturn[39;00m [43mio_open[49m[43m([49m[43mfile[49m[43m,[49m[43m [49m[38;5;241;43m*[39;49m[43margs[49m[43m,[49m[43m [49m[38;5;241;43m*[39;49m[38;5;241;43m*[39;49m[43mkwargs[49m[43m)[49m

[1;31mFileNotFoundError[0m: [Errno 2] No such file or directory: 'C:\\Users\\Vanu\\OneDrive\\Attachments\\heart_attack_prediction_dataset.csv'

